2025-01-16 18:42:19,148 INFO Бот запущен
2025-01-16 18:42:19,149 INFO Start polling
2025-01-16 18:42:19,457 INFO Run polling for bot @InsightTesBot id=7649414423 - 'WeatherBot'
2025-01-16 18:42:47,061 INFO Запрос погоды для города: moscow
2025-01-16 18:42:47,303 INFO Отправка данных пользователю: Moscow, 0.93, Снег \U0001f328
2025-01-16 18:42:47,663 INFO Update id=480730115 is handled. Duration 602 ms by bot id=7649414423
2025-01-16 18:42:50,457 INFO Update id=480730116 is not handled. Duration 223 ms by bot id=7649414423
2025-01-16 18:42:50,458 ERROR Cause exception while process update id=480730116 by bot id=7649414423
ConnectionDoesNotExistError: connection was closed in the middle of operation
Traceback (most recent call last):
  File "D:\Python\Lib\asyncio\windows_events.py", line 463, in finish_socket_func
    return ov.getresult()
           ~~~~~~~~~~~~^^
OSError: [WinError 64] Указанное сетевое имя более недоступно

During handling of the above exception, another exception occurred:

Traceback (most recent call last):
  File "D:\Python\Lib\asyncio\proactor_events.py", line 286, in _loop_reading
    length = fut.result()
  File "D:\Python\Lib\asyncio\windows_events.py", line 804, in _poll
    value = callback(transferred, key, ov)
  File "D:\Python\Lib\asyncio\windows_events.py", line 467, in finish_socket_func
    raise ConnectionResetError(*exc.args)
ConnectionResetError: [WinError 64] Указанное сетевое имя более недоступно

The above exception was the direct cause of the following exception:

Traceback (most recent call last):
  File "D:\Python\Lib\site-packages\aiogram\dispatcher\dispatcher.py", line 309, in _process_update
    response = await self.feed_update(bot, update, **kwargs)
               ^^^^^^^^^^^^^^^^^^^^^^^^^^^^^^^^^^^^^^^^^^^^^
  File "D:\Python\Lib\site-packages\aiogram\dispatcher\dispatcher.py", line 158, in feed_update
    response = await self.update.wrap_outer_middleware(
               ^^^^^^^^^^^^^^^^^^^^^^^^^^^^^^^^^^^^^^^^
    ...<7 lines>...
    )
    ^
  File "D:\Python\Lib\site-packages\aiogram\dispatcher\middlewares\error.py", line 25, in __call__
    return await handler(event, data)
           ^^^^^^^^^^^^^^^^^^^^^^^^^^
  File "D:\Python\Lib\site-packages\aiogram\dispatcher\middlewares\user_context.py", line 56, in __call__
    return await handler(event, data)
           ^^^^^^^^^^^^^^^^^^^^^^^^^^
  File "D:\Python\Lib\site-packages\aiogram\fsm\middleware.py", line 42, in __call__
    return await handler(event, data)
           ^^^^^^^^^^^^^^^^^^^^^^^^^^
  File "D:\Python\Lib\site-packages\aiogram\dispatcher\event\telegram.py", line 121, in trigger
    return await wrapped_inner(event, kwargs)
           ^^^^^^^^^^^^^^^^^^^^^^^^^^^^^^^^^^
  File "D:\Python\Lib\site-packages\aiogram\dispatcher\event\handler.py", line 43, in call
    return await wrapped()
           ^^^^^^^^^^^^^^^
  File "D:\Python\Lib\site-packages\aiogram\dispatcher\dispatcher.py", line 276, in _listen_update
    return await self.propagate_event(update_type=update_type, event=event, **kwargs)
           ^^^^^^^^^^^^^^^^^^^^^^^^^^^^^^^^^^^^^^^^^^^^^^^^^^^^^^^^^^^^^^^^^^^^^^^^^^
  File "D:\Python\Lib\site-packages\aiogram\dispatcher\router.py", line 146, in propagate_event
    return await observer.wrap_outer_middleware(_wrapped, event=event, data=kwargs)
           ^^^^^^^^^^^^^^^^^^^^^^^^^^^^^^^^^^^^^^^^^^^^^^^^^^^^^^^^^^^^^^^^^^^^^^^^
  File "D:\Python\Lib\site-packages\aiogram\dispatcher\router.py", line 141, in _wrapped
    return await self._propagate_event(
           ^^^^^^^^^^^^^^^^^^^^^^^^^^^^
        observer=observer, update_type=update_type, event=telegram_event, **data
        ^^^^^^^^^^^^^^^^^^^^^^^^^^^^^^^^^^^^^^^^^^^^^^^^^^^^^^^^^^^^^^^^^^^^^^^^
    )
    ^
  File "D:\Python\Lib\site-packages\aiogram\dispatcher\router.py", line 166, in _propagate_event
    response = await observer.trigger(event, **kwargs)
               ^^^^^^^^^^^^^^^^^^^^^^^^^^^^^^^^^^^^^^^
  File "D:\Python\Lib\site-packages\aiogram\dispatcher\event\telegram.py", line 121, in trigger
    return await wrapped_inner(event, kwargs)
           ^^^^^^^^^^^^^^^^^^^^^^^^^^^^^^^^^^
  File "D:\Python\Lib\site-packages\aiogram\dispatcher\event\handler.py", line 43, in call
    return await wrapped()
           ^^^^^^^^^^^^^^^
  File "c:\Users\den-s\Desktop\Bot_Weather\main_tg_weather.py", line 94, in registration
    existing_user = await get_user_by_username(username)
                    ^^^^^^^^^^^^^^^^^^^^^^^^^^^^^^^^^^^^
  File "c:\Users\den-s\Desktop\Bot_Weather\DB.py", line 44, in get_user_by_username
    result = await session.execute(select(User).filter_by(username=username))
             ^^^^^^^^^^^^^^^^^^^^^^^^^^^^^^^^^^^^^^^^^^^^^^^^^^^^^^^^^^^^^^^^
  File "D:\Python\Lib\site-packages\sqlalchemy\ext\asyncio\session.py", line 461, in execute
    result = await greenlet_spawn(
             ^^^^^^^^^^^^^^^^^^^^^
    ...<6 lines>...
    )
    ^
  File "D:\Python\Lib\site-packages\sqlalchemy\util\_concurrency_py3k.py", line 201, in greenlet_spawn
    result = context.throw(*sys.exc_info())
  File "D:\Python\Lib\site-packages\sqlalchemy\orm\session.py", line 2362, in execute
    return self._execute_internal(
           ~~~~~~~~~~~~~~~~~~~~~~^
        statement,
        ^^^^^^^^^^
    ...<4 lines>...
        _add_event=_add_event,
        ^^^^^^^^^^^^^^^^^^^^^^
    )
    ^
  File "D:\Python\Lib\site-packages\sqlalchemy\orm\session.py", line 2237, in _execute_internal
    conn = self._connection_for_bind(bind)
  File "D:\Python\Lib\site-packages\sqlalchemy\orm\session.py", line 2106, in _connection_for_bind
    return trans._connection_for_bind(engine, execution_options)
           ~~~~~~~~~~~~~~~~~~~~~~~~~~^^^^^^^^^^^^^^^^^^^^^^^^^^^
  File "<string>", line 2, in _connection_for_bind
  File "D:\Python\Lib\site-packages\sqlalchemy\orm\state_changes.py", line 139, in _go
    ret_value = fn(self, *arg, **kw)
  File "D:\Python\Lib\site-packages\sqlalchemy\orm\session.py", line 1189, in _connection_for_bind
    conn = bind.connect()
  File "D:\Python\Lib\site-packages\sqlalchemy\engine\base.py", line 3278, in connect
    return self._connection_cls(self)
           ~~~~~~~~~~~~~~~~~~~~^^^^^^
  File "D:\Python\Lib\site-packages\sqlalchemy\engine\base.py", line 146, in __init__
    self._dbapi_connection = engine.raw_connection()
                             ~~~~~~~~~~~~~~~~~~~~~^^
  File "D:\Python\Lib\site-packages\sqlalchemy\engine\base.py", line 3302, in raw_connection
    return self.pool.connect()
           ~~~~~~~~~~~~~~~~~^^
  File "D:\Python\Lib\site-packages\sqlalchemy\pool\base.py", line 449, in connect
    return _ConnectionFairy._checkout(self)
           ~~~~~~~~~~~~~~~~~~~~~~~~~~^^^^^^
  File "D:\Python\Lib\site-packages\sqlalchemy\pool\base.py", line 1263, in _checkout
    fairy = _ConnectionRecord.checkout(pool)
  File "D:\Python\Lib\site-packages\sqlalchemy\pool\base.py", line 712, in checkout
    rec = pool._do_get()
  File "D:\Python\Lib\site-packages\sqlalchemy\pool\impl.py", line 179, in _do_get
    with util.safe_reraise():
         ~~~~~~~~~~~~~~~~~^^
  File "D:\Python\Lib\site-packages\sqlalchemy\util\langhelpers.py", line 146, in __exit__
    raise exc_value.with_traceback(exc_tb)
  File "D:\Python\Lib\site-packages\sqlalchemy\pool\impl.py", line 177, in _do_get
    return self._create_connection()
           ~~~~~~~~~~~~~~~~~~~~~~~^^
  File "D:\Python\Lib\site-packages\sqlalchemy\pool\base.py", line 390, in _create_connection
    return _ConnectionRecord(self)
  File "D:\Python\Lib\site-packages\sqlalchemy\pool\base.py", line 674, in __init__
    self.__connect()
    ~~~~~~~~~~~~~~^^
  File "D:\Python\Lib\site-packages\sqlalchemy\pool\base.py", line 900, in __connect
    with util.safe_reraise():
         ~~~~~~~~~~~~~~~~~^^
  File "D:\Python\Lib\site-packages\sqlalchemy\util\langhelpers.py", line 146, in __exit__
    raise exc_value.with_traceback(exc_tb)
  File "D:\Python\Lib\site-packages\sqlalchemy\pool\base.py", line 896, in __connect
    self.dbapi_connection = connection = pool._invoke_creator(self)
                                         ~~~~~~~~~~~~~~~~~~~~^^^^^^
  File "D:\Python\Lib\site-packages\sqlalchemy\engine\create.py", line 643, in connect
    return dialect.connect(*cargs, **cparams)
           ~~~~~~~~~~~~~~~^^^^^^^^^^^^^^^^^^^
  File "D:\Python\Lib\site-packages\sqlalchemy\engine\default.py", line 621, in connect
    return self.loaded_dbapi.connect(*cargs, **cparams)
           ~~~~~~~~~~~~~~~~~~~~~~~~~^^^^^^^^^^^^^^^^^^^
  File "D:\Python\Lib\site-packages\sqlalchemy\dialects\postgresql\asyncpg.py", line 949, in connect
    await_only(creator_fn(*arg, **kw)),
    ~~~~~~~~~~^^^^^^^^^^^^^^^^^^^^^^^^
  File "D:\Python\Lib\site-packages\sqlalchemy\util\_concurrency_py3k.py", line 132, in await_only
    return current.parent.switch(awaitable)  # type: ignore[no-any-return,attr-defined] # noqa: E501
           ~~~~~~~~~~~~~~~~~~~~~^^^^^^^^^^^
  File "D:\Python\Lib\site-packages\sqlalchemy\util\_concurrency_py3k.py", line 196, in greenlet_spawn
    value = await result
            ^^^^^^^^^^^^
  File "D:\Python\Lib\site-packages\asyncpg\connection.py", line 2421, in connect
    return await connect_utils._connect(
           ^^^^^^^^^^^^^^^^^^^^^^^^^^^^^
    ...<20 lines>...
    )
    ^
  File "D:\Python\Lib\site-packages\asyncpg\connect_utils.py", line 1049, in _connect
    conn = await _connect_addr(
           ^^^^^^^^^^^^^^^^^^^^
    ...<6 lines>...
    )
    ^
  File "D:\Python\Lib\site-packages\asyncpg\connect_utils.py", line 886, in _connect_addr
    return await __connect_addr(params, True, *args)
           ^^^^^^^^^^^^^^^^^^^^^^^^^^^^^^^^^^^^^^^^^
  File "D:\Python\Lib\site-packages\asyncpg\connect_utils.py", line 934, in __connect_addr
    await connected
asyncpg.exceptions.ConnectionDoesNotExistError: connection was closed in the middle of operation
2025-01-16 18:45:11,668 ERROR Failed to fetch updates - TelegramNetworkError: HTTP Client says - ClientOSError: [WinError 10054] Удаленный хост принудительно разорвал существующее подключение
2025-01-16 18:45:11,669 WARNING Sleep for 1.000000 seconds and try again... (tryings = 0, bot id = 7649414423)
2025-01-16 18:46:23,157 ERROR Failed to fetch updates - TelegramNetworkError: HTTP Client says - Request timeout error
2025-01-16 18:46:23,157 WARNING Sleep for 1.457309 seconds and try again... (tryings = 1, bot id = 7649414423)
2025-01-16 18:46:42,075 INFO Connection established (tryings = 2, bot id = 7649414423)
2025-01-16 18:56:06,165 ERROR Failed to fetch updates - TelegramNetworkError: HTTP Client says - Request timeout error
2025-01-16 18:56:06,165 WARNING Sleep for 1.000000 seconds and try again... (tryings = 0, bot id = 7649414423)
2025-01-16 18:56:26,503 INFO Connection established (tryings = 1, bot id = 7649414423)
2025-01-16 18:58:37,168 ERROR Failed to fetch updates - TelegramNetworkError: HTTP Client says - Request timeout error
2025-01-16 18:58:37,168 WARNING Sleep for 1.000000 seconds and try again... (tryings = 0, bot id = 7649414423)
2025-01-16 18:59:49,154 ERROR Failed to fetch updates - TelegramNetworkError: HTTP Client says - Request timeout error
2025-01-16 18:59:49,154 WARNING Sleep for 1.049151 seconds and try again... (tryings = 1, bot id = 7649414423)
2025-01-16 19:00:11,259 ERROR Failed to fetch updates - TelegramNetworkError: HTTP Client says - ClientConnectorError: Cannot connect to host api.telegram.org:443 ssl:default [Превышен таймаут семафора]
2025-01-16 19:00:11,259 WARNING Sleep for 1.179796 seconds and try again... (tryings = 2, bot id = 7649414423)
2025-01-16 19:01:23,164 ERROR Failed to fetch updates - TelegramNetworkError: HTTP Client says - Request timeout error
2025-01-16 19:01:23,165 WARNING Sleep for 1.596485 seconds and try again... (tryings = 3, bot id = 7649414423)
2025-01-16 19:01:50,074 INFO Connection established (tryings = 4, bot id = 7649414423)
2025-01-16 19:03:39,161 ERROR Failed to fetch updates - TelegramNetworkError: HTTP Client says - Request timeout error
2025-01-16 19:03:39,161 WARNING Sleep for 1.000000 seconds and try again... (tryings = 0, bot id = 7649414423)
2025-01-16 19:04:51,158 ERROR Failed to fetch updates - TelegramNetworkError: HTTP Client says - Request timeout error
2025-01-16 19:04:51,158 WARNING Sleep for 1.135015 seconds and try again... (tryings = 1, bot id = 7649414423)
2025-01-16 19:05:13,106 INFO Connection established (tryings = 2, bot id = 7649414423)
2025-01-16 19:06:23,156 ERROR Failed to fetch updates - TelegramNetworkError: HTTP Client says - Request timeout error
2025-01-16 19:06:23,156 WARNING Sleep for 1.000000 seconds and try again... (tryings = 0, bot id = 7649414423)
2025-01-16 19:06:34,630 INFO Connection established (tryings = 1, bot id = 7649414423)
2025-01-16 19:08:13,157 ERROR Failed to fetch updates - TelegramNetworkError: HTTP Client says - Request timeout error
2025-01-16 19:08:13,158 WARNING Sleep for 1.000000 seconds and try again... (tryings = 0, bot id = 7649414423)
2025-01-16 19:08:24,498 INFO Connection established (tryings = 1, bot id = 7649414423)
2025-01-16 19:11:56,160 ERROR Failed to fetch updates - TelegramNetworkError: HTTP Client says - Request timeout error
2025-01-16 19:11:56,160 WARNING Sleep for 1.000000 seconds and try again... (tryings = 0, bot id = 7649414423)
2025-01-16 19:13:08,158 ERROR Failed to fetch updates - TelegramNetworkError: HTTP Client says - Request timeout error
2025-01-16 19:13:08,159 WARNING Sleep for 1.413227 seconds and try again... (tryings = 1, bot id = 7649414423)
2025-01-16 19:13:34,330 INFO Connection established (tryings = 2, bot id = 7649414423)
2025-01-16 19:26:58,166 ERROR Failed to fetch updates - TelegramNetworkError: HTTP Client says - Request timeout error
2025-01-16 19:26:58,166 WARNING Sleep for 1.000000 seconds and try again... (tryings = 0, bot id = 7649414423)
2025-01-16 19:27:09,500 INFO Connection established (tryings = 1, bot id = 7649414423)
2025-01-16 19:34:01,162 ERROR Failed to fetch updates - TelegramNetworkError: HTTP Client says - Request timeout error
2025-01-16 19:34:01,163 WARNING Sleep for 1.000000 seconds and try again... (tryings = 0, bot id = 7649414423)
2025-01-16 19:34:12,442 INFO Connection established (tryings = 1, bot id = 7649414423)
2025-01-16 19:36:02,168 ERROR Failed to fetch updates - TelegramNetworkError: HTTP Client says - Request timeout error
2025-01-16 19:36:02,168 WARNING Sleep for 1.000000 seconds and try again... (tryings = 0, bot id = 7649414423)
2025-01-16 19:36:15,691 INFO Connection established (tryings = 1, bot id = 7649414423)
2025-01-16 19:38:03,166 ERROR Failed to fetch updates - TelegramNetworkError: HTTP Client says - Request timeout error
2025-01-16 19:38:03,167 WARNING Sleep for 1.000000 seconds and try again... (tryings = 0, bot id = 7649414423)
2025-01-16 19:39:15,156 ERROR Failed to fetch updates - TelegramNetworkError: HTTP Client says - Request timeout error
2025-01-16 19:39:15,156 WARNING Sleep for 1.058919 seconds and try again... (tryings = 1, bot id = 7649414423)
2025-01-16 19:40:27,160 ERROR Failed to fetch updates - TelegramNetworkError: HTTP Client says - Request timeout error
2025-01-16 19:40:27,160 WARNING Sleep for 1.248939 seconds and try again... (tryings = 2, bot id = 7649414423)
2025-01-16 19:40:46,159 INFO Connection established (tryings = 3, bot id = 7649414423)
2025-01-16 20:06:59,087 INFO Polling stopped
2025-01-16 20:06:59,352 INFO Polling stopped for bot @InsightTesBot id=7649414423 - 'WeatherBot'
